<?xml version='1.0' encoding='utf-8'?>
<robot name="gen3">
  
  <link name="world" />
  <ros2_control name="KortexMultiInterfaceHardware" type="system">
    <hardware>
      <plugin>kortex_driver/KortexMultiInterfaceHardware</plugin>
      <param name="robot_ip">192.168.0.1</param>
      <param name="username">admin</param>
      <param name="password">admin</param>
      <param name="port">10000</param>
      <param name="port_realtime">10001</param>
      <param name="session_inactivity_timeout_ms">60000</param>
      <param name="connection_inactivity_timeout_ms">2000</param>
      <param name="tf_prefix">""</param>
      <param name="use_internal_bus_gripper_comm">False</param>
      <param name="gripper_joint_name">finger_joint</param>
      <param name="gripper_max_velocity">100.0</param>
      <param name="gripper_max_force">100.0</param>
    </hardware>
    <joint name="joint_1">
      <command_interface name="position">
        <param name="min">{-2*pi}</param>
        <param name="max">{2*pi}</param>
      </command_interface>
      <state_interface name="position">
        <param name="initial_value">0.0</param>
      </state_interface>
      <state_interface name="velocity" />
      <state_interface name="effort" />
    </joint>
    <joint name="joint_2">
      <command_interface name="position">
        <param name="min">-2.41</param>
        <param name="max">2.41</param>
      </command_interface>
      <state_interface name="position">
        <param name="initial_value">0.0</param>
      </state_interface>
      <state_interface name="velocity" />
      <state_interface name="effort" />
    </joint>
    <joint name="joint_3">
      <command_interface name="position">
        <param name="min">{-2*pi}</param>
        <param name="max">{2*pi}</param>
      </command_interface>
      <state_interface name="position">
        <param name="initial_value">0.0</param>
      </state_interface>
      <state_interface name="velocity" />
      <state_interface name="effort" />
    </joint>
    <joint name="joint_4">
      <command_interface name="position">
        <param name="min">-2.66</param>
        <param name="max">2.66</param>
      </command_interface>
      <state_interface name="position">
        <param name="initial_value">0.0</param>
      </state_interface>
      <state_interface name="velocity" />
      <state_interface name="effort" />
    </joint>
    <joint name="joint_5">
      <command_interface name="position">
        <param name="min">{-2*pi}</param>
        <param name="max">{2*pi}</param>
      </command_interface>
      <state_interface name="position">
        <param name="initial_value">0.0</param>
      </state_interface>
      <state_interface name="velocity" />
      <state_interface name="effort" />
    </joint>
    <joint name="joint_6">
      <command_interface name="position">
        <param name="min">-2.23</param>
        <param name="max">2.23</param>
      </command_interface>
      <state_interface name="position">
        <param name="initial_value">0.0</param>
      </state_interface>
      <state_interface name="velocity" />
      <state_interface name="effort" />
    </joint>
    <joint name="joint_7">
      <command_interface name="position">
        <param name="min">{-2*pi}</param>
        <param name="max">{2*pi}</param>
      </command_interface>
      <state_interface name="position">
        <param name="initial_value">0.0</param>
      </state_interface>
      <state_interface name="velocity" />
      <state_interface name="effort" />
    </joint>
  </ros2_control>
  <joint name="base_joint" type="fixed">
    <origin rpy="0 0 0" xyz="0 0 0" />
    <parent link="world" />
    <child link="base_link" />
  </joint>
  <link name="base_link">
    <inertial>
      <origin rpy="0 0 0" xyz="-0.000648 -0.000166 0.084487" />
      <mass value="1.697" />
      <inertia ixx="0.004622" ixy="9E-06" ixz="6E-05" iyy="0.004495" iyz="9E-06" izz="0.002079" />
    </inertial>
    <visual>
      <origin rpy="0 0 0" xyz="0 0 0" />
      <geometry>
        <mesh filename="/home/yurong/figaroh/models/others/robots/kinova_gen3/gen3/7dof/meshes/base_link.STL" />
      </geometry>
      <material name="">
        <color rgba="0.75294 0.75294 0.75294 1" />
      </material>
    </visual>
    <collision>
      <origin rpy="0 0 0" xyz="0 0 0" />
      <geometry>
        <mesh filename="/home/yurong/figaroh/models/others/robots/kinova_gen3/gen3/7dof/meshes/base_link.STL" />
      </geometry>
    </collision>
  </link>
  <link name="shoulder_link">
    <inertial>
      <origin rpy="0 0 0" xyz="-0.01345464142810788 -0.074626322574951 -0.036649261268846975" />
      <mass value="1.1746490194847434" />
      <inertia ixx="0.001766216280525824" ixy="0.0016309870324765347" ixz="0.0009900638522322078" iyy="0.006919606874451414" iyz="0.002876302188960778" izz="-0.008494460272016741" />
    </inertial>
    <visual>
      <origin rpy="0 0 0" xyz="0 0 0" />
      <geometry>
        <mesh filename="/home/yurong/figaroh/models/others/robots/kinova_gen3/gen3/7dof/meshes/shoulder_link.STL" />
      </geometry>
      <material name="">
        <color rgba="0.75294 0.75294 0.75294 1" />
      </material>
    </visual>
    <collision>
      <origin rpy="0 0 0" xyz="0 0 0" />
      <geometry>
        <mesh filename="/home/yurong/figaroh/models/others/robots/kinova_gen3/gen3/7dof/meshes/shoulder_link.STL" />
      </geometry>
    </collision>
  </link>
  <joint name="joint_1" type="revolute">
    <origin rpy="3.1416 2.7629E-18 -4.9305E-36" xyz="0 0 0.15643" />
    <parent link="base_link" />
    <child link="shoulder_link" />
    <axis xyz="0 0 1" />
    <limit effort="39" velocity="1.3963" />
  </joint>
  <link name="half_arm_1_link">
    <inertial>
      <origin rpy="0 0 0" xyz="-5.018101325169208e-05 -0.03756961297046211 0.07267846805971422" />
      <mass value="1.031384648109728" />
      <inertia ixx="0.0021076602264419953" ixy="5.224580755032068e-06" ixz="-5.524795681160264e-06" iyy="2.06470879900722e-05" iyz="-0.004540425322001923" izz="0.0032715680074172056" />
    </inertial>
    <visual>
      <origin rpy="0 0 0" xyz="0 0 0" />
      <geometry>
        <mesh filename="/home/yurong/figaroh/models/others/robots/kinova_gen3/gen3/7dof/meshes/half_arm_1_link.STL" />
      </geometry>
      <material name="">
        <color rgba="0.75294 0.75294 0.75294 1" />
      </material>
    </visual>
    <collision>
      <origin rpy="0 0 0" xyz="0 0 0" />
      <geometry>
        <mesh filename="/home/yurong/figaroh/models/others/robots/kinova_gen3/gen3/7dof/meshes/half_arm_1_link.STL" />
      </geometry>
    </collision>
  </link>
  <joint name="joint_2" type="revolute">
    <origin rpy="1.5708 2.1343E-17 -1.1102E-16" xyz="0 0.005375 -0.12838" />
    <parent link="shoulder_link" />
    <child link="half_arm_1_link" />
    <axis xyz="0 0 1" />
    <limit effort="39" lower="-2.24" upper="2.24" velocity="1.3963" />
  </joint>
  <link name="half_arm_2_link">
    <inertial>
      <origin rpy="0 0 0" xyz="-4.712694538493632e-05 -0.006329889943202162 -0.05189640605740142" />
      <mass value="1.0814845354604532" />
      <inertia ixx="0.008971779746109769" ixy="3.4678758721386717e-07" ixz="-1.0253362232578264e-05" iyy="0.006328773823739085" iyz="0.00022871611205851672" izz="0.0038657929458432248" />
    </inertial>
    <visual>
      <origin rpy="0 0 0" xyz="0 0 0" />
      <geometry>
        <mesh filename="/home/yurong/figaroh/models/others/robots/kinova_gen3/gen3/7dof/meshes/half_arm_2_link.STL" />
      </geometry>
      <material name="">
        <color rgba="0.75294 0.75294 0.75294 1" />
      </material>
    </visual>
    <collision>
      <origin rpy="0 0 0" xyz="0 0 0" />
      <geometry>
        <mesh filename="/home/yurong/figaroh/models/others/robots/kinova_gen3/gen3/7dof/meshes/half_arm_2_link.STL" />
      </geometry>
    </collision>
  </link>
  <joint name="joint_3" type="revolute">
    <origin rpy="-1.5708 1.2326E-32 -2.9122E-16" xyz="0 -0.21038 -0.006375" />
    <parent link="half_arm_1_link" />
    <child link="half_arm_2_link" />
    <axis xyz="0 0 1" />
    <limit effort="39" velocity="1.3963" />
  </joint>
  <link name="forearm_link">
    <inertial>
      <origin rpy="0 0 0" xyz="-1.6202892731211687e-05 -0.018754215330837577 -0.008215315398802584" />
      <mass value="0.994092576307687" />
      <inertia ixx="0.005663128209520809" ixy="-6.280319246288048e-07" ixz="-6.504655280491237e-07" iyy="-0.0020359114752697863" iyz="-0.0010754780009780054" izz="0.00848107224824423" />
    </inertial>
    <visual>
      <origin rpy="0 0 0" xyz="0 0 0" />
      <geometry>
        <mesh filename="/home/yurong/figaroh/models/others/robots/kinova_gen3/gen3/7dof/meshes/forearm_link.STL" />
      </geometry>
      <material name="">
        <color rgba="0.75294 0.75294 0.75294 1" />
      </material>
    </visual>
    <collision>
      <origin rpy="0 0 0" xyz="0 0 0" />
      <geometry>
        <mesh filename="/home/yurong/figaroh/models/others/robots/kinova_gen3/gen3/7dof/meshes/forearm_link.STL" />
      </geometry>
    </collision>
  </link>
  <joint name="joint_4" type="revolute">
    <origin rpy="1.5708 -6.6954E-17 -1.6653E-16" xyz="0 0.006375 -0.21038" />
    <parent link="half_arm_2_link" />
    <child link="forearm_link" />
    <axis xyz="0 0 1" />
    <limit effort="39" lower="-2.57" upper="2.57" velocity="1.3963" />
  </joint>
  <link name="spherical_wrist_1_link">
    <inertial>
      <origin rpy="0 0 0" xyz="6.45250108019768e-07 -0.005576665236612655 0.003780745708449326" />
      <mass value="0.8016193244823407" />
      <inertia ixx="0.0016942475092427314" ixy="1.1327108465845678e-07" ixz="-3.6212132002885215e-07" iyy="0.00039106745055575616" iyz="3.123202852836256e-05" izz="0.0017050143548163693" />
    </inertial>
    <visual>
      <origin rpy="0 0 0" xyz="0 0 0" />
      <geometry>
        <mesh filename="/home/yurong/figaroh/models/others/robots/kinova_gen3/gen3/7dof/meshes/spherical_wrist_1_link.STL" />
      </geometry>
      <material name="">
        <color rgba="0.75294 0.75294 0.75294 1" />
      </material>
    </visual>
    <collision>
      <origin rpy="0 0 0" xyz="0 0 0" />
      <geometry>
        <mesh filename="/home/yurong/figaroh/models/others/robots/kinova_gen3/gen3/7dof/meshes/spherical_wrist_1_link.STL" />
      </geometry>
    </collision>
  </link>
  <joint name="joint_5" type="revolute">
    <origin rpy="-1.5708 2.2204E-16 -6.373E-17" xyz="0 -0.20843 -0.006375" />
    <parent link="forearm_link" />
    <child link="spherical_wrist_1_link" />
    <axis xyz="0 0 1" />
    <limit effort="9" velocity="1.2218" />
  </joint>
  <link name="spherical_wrist_2_link">
    <inertial>
      <origin rpy="0 0 0" xyz="1.0097206979503346e-06 -0.0344651405995989 -0.0057030158355859525" />
      <mass value="0.7992224156855354" />
      <inertia ixx="0.0022357854742970015" ixy="-4.58167197476792e-07" ixz="-1.955549560927486e-08" iyy="-0.000821396659968852" iyz="-0.0004188761074648455" izz="0.003471017927597143" />
    </inertial>
    <visual>
      <origin rpy="0 0 0" xyz="0 0 0" />
      <geometry>
        <mesh filename="/home/yurong/figaroh/models/others/robots/kinova_gen3/gen3/7dof/meshes/spherical_wrist_2_link.STL" />
      </geometry>
      <material name="">
        <color rgba="0.75294 0.75294 0.75294 1" />
      </material>
    </visual>
    <collision>
      <origin rpy="0 0 0" xyz="0 0 0" />
      <geometry>
        <mesh filename="/home/yurong/figaroh/models/others/robots/kinova_gen3/gen3/7dof/meshes/spherical_wrist_2_link.STL" />
      </geometry>
    </collision>
  </link>
  <joint name="joint_6" type="revolute">
    <origin rpy="1.5708 9.2076E-28 -8.2157E-15" xyz="0 0.00017505 -0.10593" />
    <parent link="spherical_wrist_1_link" />
    <child link="spherical_wrist_2_link" />
    <axis xyz="0 0 1" />
    <limit effort="9" lower="-2.09" upper="2.09" velocity="1.2218" />
  </joint>
  <link name="bracelet_link">
    <inertial>
      <origin rpy="0 0 0" xyz="0.0001337068213806595 -0.00014676121736605948 -0.04679670652203298" />
      <mass value="0.8313621489393325" />
      <inertia ixx="0.002052208832989246" ixy="2.205603796144553e-07" ixz="9.826334509636378e-06" iyy="0.0020683374807878847" iyz="-1.3485973882290528e-05" izz="0.00045574041459895456" />
    </inertial>
    <visual>
      <origin rpy="0 0 0" xyz="0 0 0" />
      <geometry>
        <mesh filename="/home/yurong/figaroh/models/others/robots/kinova_gen3/gen3/7dof/meshes/bracelet_no_vision_link.STL" />
      </geometry>
      <material name="">
        <color rgba="0.75294 0.75294 0.75294 1" />
      </material>
    </visual>
    <collision>
      <origin rpy="0 0 0" xyz="0 0 0" />
      <geometry>
        <mesh filename="/home/yurong/figaroh/models/others/robots/kinova_gen3/gen3/7dof/meshes/bracelet_no_vision_link.STL" />
      </geometry>
    </collision>
  </link>
  <joint name="joint_7" type="revolute">
    <origin rpy="-1.5708 -5.5511E-17 9.6396E-17" xyz="0 -0.10593 -0.00017505" />
    <parent link="spherical_wrist_2_link" />
    <child link="bracelet_link" />
    <axis xyz="0 0 1" />
    <limit effort="9" velocity="1.2218" />
  </joint>
  <link name="end_effector_link" />
  <joint name="end_effector" type="fixed">
    <origin rpy="3.14159265358979 1.09937075168372E-32 0" xyz="0 0 -0.0615250000000001" />
    <parent link="bracelet_link" />
    <child link="end_effector_link" />
    <axis xyz="0 0 0" />
  </joint>
  <link name="tool_frame" />
  <joint name="tool_frame_joint" type="fixed">
    <origin rpy="0 0 0" xyz="0 0 0" />
    <parent link="end_effector_link" />
    <child link="tool_frame" />
    <axis xyz="0 0 0" />
  </joint>
  <link name="FT_sensor_mounting">
    <inertial>
      <origin rpy="0 0 0" xyz="-9.4473E-05 0.00063177 0.010132" />
      <mass value="0.14931" />
      <inertia ixx="4.8806E-05" ixy="3.2223E-08" ixz="-1.0415E-07" iyy="5.5473E-05" iyz="1.3709E-07" izz="8.9696E-05" />
    </inertial>
    <visual>
      <origin rpy="0 0 0" xyz="0 0 0" />
      <geometry>
        
      </geometry>
      <material name="">
        <color rgba="0.6902 0.61176 0.52941 1" />
      </material>
    </visual>
    <collision>
      <origin rpy="0 0 0" xyz="0 0 0.011" />
      <geometry>
        <cylinder length="0.028" radius="0.035" />
      </geometry>
    </collision>
    <collision>
      <origin rpy="1.57 0 0" xyz="0 0.051 0.0115" />
      <geometry>
        <cylinder length="0.032" radius="0.0065" />
      </geometry>
    </collision>
    <collision>
      <origin rpy="0 0 0" xyz="0 0 0.03" />
      <geometry>
        <cylinder length="0.01" radius="0.0315" />
      </geometry>
    </collision>
  </link>
  <link name="FT_sensor_imu">
    <inertial>
      <origin rpy="0 0 0" xyz="-7.28164825396643E-05 1.54951151759942E-05 -0.00279059266096084" />
      <mass value="0.00841533584597687" />
      <inertia ixx="4.36835040253875E-07" ixy="-6.98609475825204E-11" ixz="-6.08397676352913E-15" iyy="4.41035649008913E-07" iyz="1.1033148379698E-11" izz="8.74962095262403E-07" />
    </inertial>
  </link>
  <joint name="mounting_to_imu" type="fixed">
    <origin rpy="0 0 0" xyz="0 0 0.0093" />
    <parent link="FT_sensor_mounting" />
    <child link="FT_sensor_imu" />
    <axis xyz="0 0 0" />
  </joint>
  <link name="FT_sensor_wrench">
    <inertial>
      <origin rpy="0 0 0" xyz="-1.9753E-07 0.00017443 -0.0070758" />
      <mass value="0.081117" />
      <inertia ixx="2.1858E-05" ixy="-1.9153E-12" ixz="3.7592E-11" iyy="2.2215E-05" iyz="-4.9937E-08" izz="4.0048E-05" />
    </inertial>
  </link>
  <joint name="mounting_to_wrench" type="fixed">
    <origin rpy="0 0 0" xyz="0 0 0.035" />
    <parent link="FT_sensor_mounting" />
    <child link="FT_sensor_wrench" />
    <axis xyz="0 0 0" />
  </joint>
  <link name="FT_sensor_mech1">
    </link>
  <joint name="mounting_to_mech1" type="fixed">
    <origin rpy="1.5625 0 -1.5708" xyz="-0.032879 0 0.0105" />
    <parent link="FT_sensor_mounting" />
    <child link="FT_sensor_mech1" />
    <axis xyz="0 0 0" />
  </joint>
  <link name="FT_sensor_mech2">
    </link>
  <joint name="mounting_to_mech2" type="fixed">
    <origin rpy="1.5708 0 0" xyz="0 -0.032879 0.0105" />
    <parent link="FT_sensor_mounting" />
    <child link="FT_sensor_mech2" />
    <axis xyz="0 0 0" />
  </joint>
  <link name="FT_sensor_mech3">
    </link>
  <joint name="mounting_to_mech3" type="fixed">
    <origin rpy="1.5708 0 1.5708" xyz="0.032879 0 0.0105" />
    <parent link="FT_sensor_mounting" />
    <child link="FT_sensor_mech3" />
    <axis xyz="0 0 0" />
  </joint>
  <link name="FT_adapter">
    <inertial>
      <origin rpy="0 0 0" xyz="0.001329828523918 0.000509434161397 0.017297595549827" />
      <mass value="0.12" />
      <inertia ixx="5.40350E-05" ixy="8.13203E-08" ixz="1.70226E-06" iyy="5.69809E-05" iyz="1.05961E-06" izz="8.81951E-05" />
    </inertial>
    <visual name="adapter">
      <origin rpy="0 0 0" xyz="0 0 0.0" />
      <geometry>
        
      </geometry>
      <material name="">
        <color rgba="0.6902 0.61176 0.52941 1" />
      </material>
    </visual>
    <collision>
      <origin rpy="0 0 0" xyz="0 0 0.015" />
      <geometry>
        <cylinder length="0.03" radius="0.0075" />
      </geometry>
    </collision>
  </link>
  <joint name="kinova_to_adapter" type="fixed">
    <parent link="end_effector_link" />
    <child link="FT_adapter" />
    <origin rpy="0.0 0.0 0.0" xyz="0.0 0.0 0.03" />
  </joint>
  <joint name="adapter_to_FT" type="fixed">
    <parent link="FT_adapter" />
    <child link="FT_sensor_mounting" />
    <origin rpy="0.0 0.0 0.0" xyz="0.0 0.0 0.0" />
  </joint>
</robot>