<?xml version='1.0' encoding='utf-8'?>
<robot name="airbot_play_v3_0_gripper">
  <link name="base_link">
    <inertial>
      <origin xyz="-0.010729 -0.00017015 0.041712" rpy="0 0 0" />
      <mass value="0.77705" />
      <inertia ixx="0.0008453" ixy="-7.4E-06" ixz="2.06E-05" iyy="0.0011821" iyz="-6.4E-06" izz="0.0012442" />
    </inertial>
    <visual>
      <origin xyz="0 0 0" rpy="0 0 0" />
      <geometry>
        <mesh filename="/home/yurong/figaroh/models/others/robots/airbot_play_v3_0_gripper/meshes/base_link.STL" />
      </geometry>
      <material name="">
        <color rgba="0.75294 0.75294 0.75294 1" />
      </material>
    </visual>
    <collision>
      <origin xyz="0 0 0" rpy="0 0 0" />
      <geometry>
        <mesh filename="/home/yurong/figaroh/models/others/robots/airbot_play_v3_0_gripper/meshes/base_link.STL" />
      </geometry>
    </collision>
  </link>
  <link name="link1">
    <inertial>
      <origin xyz="-0.01483909935207219 -0.0015726343309683272 0.004597801375802844" rpy="0 0 0" />
      <mass value="0.6570518130587986" />
      <inertia ixx="-0.005693047465296278" ixy="-0.005460256373727025" ixz="0.00726087643201012" iyy="0.0021168179713171517" iyz="-0.00827635746709018" izz="-0.05593299044552633" />
    </inertial>
    <visual>
      <origin xyz="0 0 0" rpy="0 0 0" />
      <geometry>
        <mesh filename="/home/yurong/figaroh/models/others/robots/airbot_play_v3_0_gripper/meshes/link1.STL" />
      </geometry>
      <material name="">
        <color rgba="0.89804 0.91765 0.92941 1" />
      </material>
    </visual>
    <collision>
      <origin xyz="0 0 0" rpy="0 0 0" />
      <geometry>
        <mesh filename="/home/yurong/figaroh/models/others/robots/airbot_play_v3_0_gripper/meshes/link1.STL" />
      </geometry>
    </collision>
  </link>
  <joint name="joint1" type="revolute">
    <origin xyz="0 0 0.1172" rpy="0 0 0" />
    <parent link="base_link" />
    <child link="link1" />
    <axis xyz="0 0 1" />
    <limit lower="-3.14" upper="2.09" effort="18" velocity="3.14" />
  <dynamics damping="0.017587529483287567" friction="0.3015441873440928" /></joint>
  <link name="link2">
    <inertial>
      <origin xyz="-0.022325914761573695 0.07688035565647762 0.011531301687333415" rpy="0 0 0" />
      <mass value="0.7219164501646103" />
      <inertia ixx="-0.09004743207029006" ixy="-0.19296424199436898" ixz="-0.11747827331983877" iyy="0.060381729760548127" iyz="-0.1041852303964119" izz="-0.061450712061431725" />
    </inertial>
    <visual>
      <origin xyz="0 0 0" rpy="0 0 0" />
      <geometry>
        <mesh filename="/home/yurong/figaroh/models/others/robots/airbot_play_v3_0_gripper/meshes/link2.STL" />
      </geometry>
      <material name="">
        <color rgba="0.75294 0.75294 0.75294 1" />
      </material>
    </visual>
    <collision>
      <origin xyz="0 0 0" rpy="0 0 0" />
      <geometry>
        <mesh filename="/home/yurong/figaroh/models/others/robots/airbot_play_v3_0_gripper/meshes/link2.STL" />
      </geometry>
    </collision>
  </link>
  <joint name="joint2" type="revolute">
    <origin xyz="0 0 0" rpy="1.5708 -2.7549 0" />
    <parent link="link1" />
    <child link="link2" />
    <axis xyz="0 0 1" />
    <limit lower="-2.96" upper="0.17" effort="18" velocity="3.14" />
  <dynamics damping="-0.31141649954428463" friction="0.8587953363732699" /></joint>
  <link name="link3">
    <inertial>
      <origin xyz="-0.05697984414991346 0.020671259343061514 0.0678079215906704" rpy="0 0 0" />
      <mass value="0.4362936183278606" />
      <inertia ixx="0.001044299599329996" ixy="0.12274133644796364" ixz="0.025291942524736363" iyy="-0.04391788975851622" iyz="0.06358733880088033" izz="-0.06913599960237714" />
    </inertial>
    <visual>
      <origin xyz="0 0 0" rpy="0 0 0" />
      <geometry>
        <mesh filename="/home/yurong/figaroh/models/others/robots/airbot_play_v3_0_gripper/meshes/link3.STL" />
      </geometry>
      <material name="">
        <color rgba="0.75294 0.75294 0.75294 1" />
      </material>
    </visual>
    <collision>
      <origin xyz="0 0 0" rpy="0 0 0" />
      <geometry>
        <mesh filename="/home/yurong/figaroh/models/others/robots/airbot_play_v3_0_gripper/meshes/link3.STL" />
      </geometry>
    </collision>
  </link>
  <joint name="joint3" type="revolute">
    <origin xyz="0.27009 0 0" rpy="0 0 1.9575" />
    <parent link="link2" />
    <child link="link3" />
    <axis xyz="0 0 1" />
    <limit lower="-0.087" upper="3.14" effort="18" velocity="3.14" />
  <dynamics damping="0.016348215713227254" friction="0.5584900613272059" /></joint>
  <link name="link4">
    <inertial>
      <origin xyz="0.01441562131522468 0.03375344874673665 -0.18431868767234671" rpy="0 0 0" />
      <mass value="0.46063228100996817" />
      <inertia ixx="-0.02052182066980607" ixy="-0.0030779033251656573" ixz="-0.011524702478993619" iyy="-0.06839183945571699" iyz="0.01036345578334368" izz="0.0055854158878551234" />
    </inertial>
    <visual>
      <origin xyz="0 0 0" rpy="0 0 0" />
      <geometry>
        <mesh filename="/home/yurong/figaroh/models/others/robots/airbot_play_v3_0_gripper/meshes/link4.STL" />
      </geometry>
      <material name="">
        <color rgba="1 1 1 1" />
      </material>
    </visual>
    <collision>
      <origin xyz="0 0 0" rpy="0 0 0" />
      <geometry>
        <mesh filename="/home/yurong/figaroh/models/others/robots/airbot_play_v3_0_gripper/meshes/link4.STL" />
      </geometry>
    </collision>
  </link>
  <joint name="joint4" type="revolute">
    <origin xyz="0 0.30854 0" rpy="-1.5708 -1.5708 0" />
    <parent link="link3" />
    <child link="link4" />
    <axis xyz="0 0 1" />
    <limit lower="-2.96" upper="2.96" effort="3" velocity="6.28" />
  <dynamics damping="0.07792529385843149" friction="0.10026255136388931" /></joint>
  <link name="link5">
    <inertial>
      <origin xyz="-0.039232584328648464 -0.008534499199672044 -0.014203984658237112" rpy="0 0 0" />
      <mass value="0.47423926496001856" />
      <inertia ixx="0.0027100654574142512" ixy="-0.006424598551039914" ixz="0.001109465411555635" iyy="0.0013570158600454646" iyz="0.005901941477090494" izz="-0.008732992943683189" />
    </inertial>
    <visual>
      <origin xyz="0 0 0" rpy="0 0 0" />
      <geometry>
        <mesh filename="/home/yurong/figaroh/models/others/robots/airbot_play_v3_0_gripper/meshes/link5.STL" />
      </geometry>
      <material name="">
        <color rgba="0.89804 0.91765 0.92941 1" />
      </material>
    </visual>
    <collision>
      <origin xyz="0 0 0" rpy="0 0 0" />
      <geometry>
        <mesh filename="/home/yurong/figaroh/models/others/robots/airbot_play_v3_0_gripper/meshes/link5.STL" />
      </geometry>
    </collision>
  </link>
  <joint name="joint5" type="revolute">
    <origin xyz="0 0 0" rpy="1.5708 0 0" />
    <parent link="link4" />
    <child link="link5" />
    <axis xyz="0 0 1" />
    <limit lower="-1.74" upper="1.74" effort="3" velocity="6.28" />
  <dynamics damping="0.020496401456674296" friction="0.09831985571512654" /></joint>
  <link name="link6">
    <inertial>
      <origin xyz="0.016521368373954258 0.020636968514396916 -0.12481850761856518" rpy="0 0 0" />
      <mass value="0.6739165724787437" />
      <inertia ixx="-0.004938738287505667" ixy="0.003643434295278775" ixz="0.0014788208184742754" iyy="-0.01588935399871435" iyz="0.00013103059894053613" izz="-0.007418867785930732" />
    </inertial>
    <visual>
      <origin xyz="0 0 0" rpy="0 0 0" />
      <geometry>
        <mesh filename="/home/yurong/figaroh/models/others/robots/airbot_play_v3_0_gripper/meshes/link6.STL" />
      </geometry>
      <material name="">
        <color rgba="0.69804 0.69804 0.69804 1" />
      </material>
    </visual>
    <collision>
      <origin xyz="0 0 0" rpy="0 0 0" />
      <geometry>
        <mesh filename="/home/yurong/figaroh/models/others/robots/airbot_play_v3_0_gripper/meshes/link6.STL" />
      </geometry>
    </collision>
  </link>
  <joint name="joint6" type="revolute">
    <origin xyz="0 0.26145 0" rpy="-1.5708 0 0" />
    <parent link="link5" />
    <child link="link6" />
    <axis xyz="0 0 1" />
    <limit lower="-3.14" upper="3.14" effort="3" velocity="6.28" />
  <dynamics damping="0.028158904193929964" friction="0.08351915835242865" /></joint>
  
  
</robot>